Workbook

Sheet Tabella riassuntiva
B1: Legenda colori: | E1: 001B
C2: Dismesso
C3: Richiede lavori
C4: Sfioro di testa rete, si attiva per rigurgito
C5: dati aggiornati post 01/01/2026
AC6: Sistemare formula mettendo Qs>=20 e non solo > | AD6: Sistemare formula mettendo Qs>=20 e non solo >
B7: A destra i campi su SAP | D7: CODICE_PROVINCIA_MANUFATTO | E7: CODICE_PROVINCIA_SCARICO | F7: NOTE | K7: DEPURATORE_ASSOCIATO | L7: RECAPITO_EMISSARIO | M7: TIPO_SCARICO | O7: TIPO_MANUFATTO | P7: ABITANTI_EQUIVALENTI_CIVILI | Q7: ABITANTI_EQUIVALENTI_INDUSTRIA | R7: ABITANTI_EQUIV_TOTALI | S7: PORTATA_REFLUA_CIVILE | T7: PORTATA_REFLUA_INDUSTRIALE | U7: PORTATA_NERA_MEDIA_ANNUA | V7: PORTATA_SOGLIA | W7: PORTATA_AVVIARE_DEPURAZIONE | X7: RAPP_PSOGLIA_MEDIA_ANNUA | Y7: PORT_SOGLIA_PORT_DEPURAZIONE | Z7: BACINO>10.000 AE | AA7: RAPP_PSOGLIA_AVVIARE_DEPURAZ | AB7: TIPOLOGIA | AC7: CONF_NORM_PORT_NERA | AE7: VASCA_REGOLAMENTO_REG | AF7: BACINO_PROPRIO | AG7: PORTATA_METEORICA_INGRESSO | AH7: PORTATA_LIMITE_INGRESSO | AI7: MANUFATTO_LIMITANTE | AJ7: PORTATA_SPECIFICA_SCARICO | AK7: SUPERFICIE_IMPERMEABILE | AM7: VASCA_TUTELA_USO_ACQUE | AO7: SCADENZA_AUTORIZ_PROVINCIA | AP7: NR_ATTO_PROVINCIA | AQ7: CONSORZIO_COMPETENTE | AR7: SCADENZA_AUTORIZ_CONSORZIO | AS7: NR_ATTO_CONSORZIO
A8: Mese modifica | C8: Codice | D8: Cod Prov Manufa SF | E8: Cod Prov Scarico SF | F8: Note | G8: COMUNE | H8: LOCALITA | I8: UBICAZIONE | J8: Coordinate | K8: DEPURATORE ASSOCIATO | L8: RECAPITO EMISSARIO | M8: Tipo di scarico | N8: Scarica a lago o suolo? (serve per il calcolo automatico di Pavv) | O8: TIPO | P8: AE CIV | Q8: AE IND | R8: AE TOT | S8: Q CIV [l/s] | T8: Q IND [l/s] | U8: Qnm [l/s] | V8: Qs [l/s] | W8: Pavv [l/s] | X8: Qs/Qnm | Y8: Qs > Pavv | Z8: 10'000 AE | AA8: Qs/Pavv | AB8: TIPOLOGIA | AC8: è conforme? | AD8: Qs>20 | AE8: Vasca RR | AF8: Bacino proprio (ha) | AG8: Q meteo in ingresso al manufatto (l/s) | AH8: Q limite ingresso al manufatto (l/s) | AI8: Manufatto limitante | AJ8: Portata specifica allo scarico [l/s haimp] | AK8: Sup imp [ha] | AL8: Qscolmata [l/s] | AM8: Vasca PTUA | AN8: dotazione sistema di rilevamento automatico dell'attivazione (SI/NO) | AO8: Scadenza autorizzazione Provincia | AP8: Atto Provincia n° | AQ8: Consorzio competente | AR8: Scadenza concessione Consorzio | AS8: Atto Consorzio n° | AT8: Note AUT./CONC.
C9: SF-BGN-CAM2 | E9: =D9&""&$E$1 -> 001B | F9: dismesso, pozzetto di testa | G9: Bagnolo San Vito | H9: Campione | J9: 45.07802541119757, 10.822675720904686 | K9: Bagnolo san Vito (Campione) | R9: =P9+Q9 -> 0 | U9: =T9+S9 -> 0 | AC9: =IF(O9="di testa rete",IF(V9>W9,"SI","NO"),IF(V9>20,IF(V9>(W9+0.001),"SI","NO"),IF(V9<(W9+0.001),"NO",IF(O9="in testa impianto sollevamento","SI",IF(O9="in testa impianto di depurazione",IF(K9="Ponti sul Mincio (Capoluogo)","NO","SI"),"NO"))))) -> NO | AI9: =IF(AG9>AH9, "Manufatto limitante", " ") | AK9: =((MIN(AG9:AH9))-V9)/AJ9 -> #DIV/0! | AL9: =MIN(AG9:AH9)-V9 -> 0 | AO9: - | AP9: - | AQ9: - | AR9: - | AS9: - | AT9: -
C10: SF-BGN-PRI | E10: =D10&""&$E$1 -> 001B | F10: dismesso | G10: Bagnolo San Vito | H10: Capoluogo | I10: Da ex sala valvole sollevamento | J10: 45.072441, 10.874700 | K10: Bagnolo san Vito (Capoluogo) | R10: =P10+Q10 -> 0 | U10: =T10+S10 -> 0 | AC10: =IF(O10="di testa rete",IF(V10>W10,"SI","NO"),IF(V10>20,IF(V10>(W10+0.001),"SI","NO"),IF(V10<(W10+0.001),"NO",IF(O10="in testa impianto sollevamento","SI",IF(O10="in testa impianto di depurazione",IF(K10="Ponti sul Mincio (Capoluogo)","NO","SI"),"NO"))))) -> NO | AI10: =IF(AG10>AH10, "Manufatto limitante", " ") | AK10: =((MIN(AG10:AH10))-V10)/AJ10 -> #DIV/0! | AL10: =MIN(AG10:AH10)-V10 -> 0 | AO10: - | AP10: - | AQ10: - | AR10: - | AS10: - | AT10: -
C11: SF-BGV-PAR2 | E11: =D11&""&$E$1 -> 001B | F11: dismesso 2021 | G11: Borgo Virgilio | H11: Pietole | I11: via Parma 29 | J11: 45.11421155095645, 10.81829287848042 | K11: Borgo Virgilio (Pietole) | M11: - | R11: =P11+Q11 -> 0 | U11: =T11+S11 -> 0 | AC11: =IF(O11="di testa rete",IF(V11>W11,"SI","NO"),IF(V11>20,IF(V11>(W11+0.001),"SI","NO"),IF(V11<(W11+0.001),"NO",IF(O11="in testa impianto sollevamento","SI",IF(O11="in testa impianto di depurazione",IF(K11="Ponti sul Mincio (Capoluogo)","NO","SI"),"NO"))))) -> NO | AI11: =IF(AG11>AH11, "Manufatto limitante", " ") | AK11: =((MIN(AG11:AH11))-V11)/AJ11 -> #DIV/0! | AL11: =MIN(AG11:AH11)-V11 -> 0 | AO11: - | AP11: - | AQ11: - | AR11: - | AS11: - | AT11: -
C12: SF-BGV-SCO | E12: =D12&""&$E$1 -> 001B | F12: dismesso | G12: Borgo Virgilio | H12: Scorzarolo | I12: depuratore | J12: 45.05649967907035, 10.685944116289598 | K12: Borgo Virgilio (Scorzarolo) | R12: =P12+Q12 -> 0 | U12: =T12+S12 -> 0 | AC12: =IF(O12="di testa rete",IF(V12>W12,"SI","NO"),IF(V12>20,IF(V12>(W12+0.001),"SI","NO"),IF(V12<(W12+0.001),"NO",IF(O12="in testa impianto sollevamento","SI",IF(O12="in testa impianto di depurazione",IF(K12="Ponti sul Mincio (Capoluogo)","NO","SI"),"NO"))))) -> NO | AI12: =IF(AG12>AH12, "Manufatto limitante", " ") | AK12: =((MIN(AG12:AH12))-V12)/AJ12 -> #DIV/0! | AL12: =MIN(AG12:AH12)-V12 -> 0 | AP12: - | AQ12: - | AR12: - | AS12: - | AT12: -
C13: SF-BZZ-BZZ1 | E13: =D13&""&$E$1 -> 001B | F13: Dismesso, bypass della grigliatura, scaricava tramite pompe | G13: Bozzolo | H13: Capoluogo | I13: depuratore | J13: 45.056500, 10.685944 | K13: Bozzolo (capoluogo) | O13: in testa impianto di depurazione | R13: =P13+Q13 -> 0 | U13: =T13+S13 -> 0 | AC13: =IF(O13="di testa rete",IF(V13>W13,"SI","NO"),IF(V13>20,IF(V13>(W13+0.001),"SI","NO"),IF(V13<(W13+0.001),"NO",IF(O13="in testa impianto sollevamento","SI",IF(O13="in testa impianto di depurazione",IF(K13="Ponti sul Mincio (Capoluogo)","NO","SI"),"NO"))))) -> NO | AI13: =IF(AG13>AH13, "Manufatto limitante", " ") | AK13: =((MIN(AG13:AH13))-V13)/AJ13 -> #DIV/0! | AL13: =MIN(AG13:AH13)-V13 -> 0 | AO13: 46147 | AP13: PD/497 del 05/05/2022 | AQ13: - | AR13: - | AS13: -
C14: SF-CRB-200 | E14: =D14&""&$E$1 -> 001B | F14: dismesso 2021 | G14: Carbonara di Po | H14: Capoluogo | I14: via Arginino | J14: 45.02955985139492, 11.216392589483148 | K14: Carbonara di Po | L14: fosso | AC14: =IF(O14="di testa rete",IF(V14>W14,"SI","NO"),IF(V14>20,IF(V14>(W14+0.001),"SI","NO"),IF(V14<(W14+0.001),"NO",IF(O14="in testa impianto sollevamento","SI",IF(O14="in testa impianto di depurazione",IF(K14="Ponti sul Mincio (Capoluogo)","NO","SI"),"NO"))))) -> NO | AO14: - | AP14: - | AQ14: - | AR14: - | AS14: - | AT14: -
C15: SF-DSL-XXS | E15: =D15&""&$E$1 -> 001B | F15: DISMESSO | G15: Dosolo | H15: Villastrada | J15: 44.97978, 10.64232 | K15: Dosolo | AC15: =IF(O15="di testa rete",IF(V15>W15,"SI","NO"),IF(V15>20,IF(V15>(W15+0.001),"SI","NO"),IF(V15<(W15+0.001),"NO",IF(O15="in testa impianto sollevamento","SI",IF(O15="in testa impianto di depurazione",IF(K15="Ponti sul Mincio (Capoluogo)","NO","SI"),"NO"))))) -> NO | AO15: - | AP15: - | AQ15: - | AR15: - | AS15: - | AT15: -
C16: SF-GNZ-GNZ | E16: =D16&""&$E$1 -> 001B | F16: dismesso | G16: Gonzaga | J16: 44.95088325927053, 10.829668978954954 | K16: Gonzaga (capoluogo) | R16: =P16+Q16 -> 0 | AC16: =IF(O16="di testa rete",IF(V16>W16,"SI","NO"),IF(V16>20,IF(V16>(W16+0.001),"SI","NO"),IF(V16<(W16+0.001),"NO",IF(O16="in testa impianto sollevamento","SI",IF(O16="in testa impianto di depurazione",IF(K16="Ponti sul Mincio (Capoluogo)","NO","SI"),"NO"))))) -> NO | AI16: =IF(AG16>AH16, "Manufatto limitante", " ") | AK16: =((MIN(AG16:AH16))-V16)/AJ16 -> #DIV/0! | AL16: =MIN(AG16:AH16)-V16 -> 0 | AO16: - | AP16: - | AQ16: - | AR16: - | AS16: - | AT16: -
C17: SF-GZZ-EUR1 | E17: =D17&""&$E$1 -> 001B | F17: dismesso | G17: Gazzuolo | J17: 45.06331794020736, 10.5804572346409 | K17: Gazzuolo | R17: =P17+Q17 -> 0 | AC17: =IF(O17="di testa rete",IF(V17>W17,"SI","NO"),IF(V17>20,IF(V17>(W17+0.001),"SI","NO"),IF(V17<(W17+0.001),"NO",IF(O17="in testa impianto sollevamento","SI",IF(O17="in testa impianto di depurazione",IF(K17="Ponti sul Mincio (Capoluogo)","NO","SI"),"NO"))))) -> NO | AI17: =IF(AG17>AH17, "Manufatto limitante", " ") | AK17: =((MIN(AG17:AH17))-V17)/AJ17 -> #DIV/0! | AL17: =MIN(AG17:AH17)-V17 -> 0 | AO17: - | AP17: - | AQ17: - | AR17: - | AS17: - | AT17: -
C18: SF-GZZ-MAR | E18: =D18&""&$E$1 -> 001B | F18: dismesso | G18: Gazzuolo | J18: 45.059230920749336, 10.579547107889386 | K18: Gazzuolo | R18: =P18+Q18 -> 0 | U18: =T18+S18 -> 0 | AC18: =IF(O18="di testa rete",IF(V18>W18,"SI","NO"),IF(V18>20,IF(V18>(W18+0.001),"SI","NO"),IF(V18<(W18+0.001),"NO",IF(O18="in testa impianto sollevamento","SI",IF(O18="in testa impianto di depurazione",IF(K18="Ponti sul Mincio (Capoluogo)","NO","SI"),"NO"))))) -> NO | AI18: =IF(AG18>AH18, "Manufatto limitante", " ") | AK18: =((MIN(AG18:AH18))-V18)/AJ18 -> #DIV/0! | AL18: =MIN(AG18:AH18)-V18 -> 0 | AO18: - | AP18: - | AQ18: - | AR18: - | AS18: - | AT18: -
C19: SF-MN-7DIC | E19: =D19&""&$E$1 -> 001B | F19: Dismesso novembre 2020 | G19: Mantova | H19: Belfiore | I19: Belfiore | J19: 45.15703, 10.77016 | K19: Mantova | L19: Lago Superiore | N19: si | Q19: 0 | R19: =P19+Q19 -> 0 | T19: 0 | U19: =T19+S19 -> 0 | X19: =V19/U19 -> #DIV/0! | Y19: =IF(V19>W19, "è in grado", "non è in grado") -> non è in grado | Z19: =IF(R19>10000, "sottende", "non sottende") -> non sottende | AA19: =V19/W19 -> #DIV/0! | AB19: =IF(R19>10000, "B", IF(AA19>=2, "A", "B")) -> #DIV/0! | AC19: =IF(O19="di testa rete",IF(V19>W19,"SI","NO"),IF(V19>20,IF(V19>(W19+0.001),"SI","NO"),IF(V19<(W19+0.001),"NO",IF(O19="in testa impianto sollevamento","SI",IF(O19="in testa impianto di depurazione",IF(K19="Ponti sul Mincio (Capoluogo)","NO","SI"),"NO"))))) -> NO | AD19: =IF(V19>20, "Si", "No") -> No | AE19: non occorre | AF19: 0.11 | AG19: 26 | AH19: 703 | AI19: =IF(AG19>AH19, "Manufatto limitante", " ") | AJ19: 0 | AK19: =((MIN(AG19:AH19))-V19)/AJ19 -> #DIV/0! | AL19: =MIN(AG19:AH19)-V19 -> 26 | AM19: non occorre | AO19: - | AP19: - | AQ19: - | AR19: - | AS19: - | AT19: -
C20: SF-MN-BEL | E20: =D20&""&$E$1 -> 001B | F20: In dismissione a marzo 24 | G20: Mantova | H20: Belfiore | I20: Belfiore | J20: 45.15705, 10.76941 | K20: Mantova | L20: Lago Superiore | N20: si | O20: di rete | P20: 866 | Q20: 0 | R20: =P20+Q20 -> 866 | S20: 2.04 | T20: 0 | U20: =T20+S20 -> 2.04 | V20: 22.54 | W20: 10.02 | X20: =V20/U20 -> 11.04902 | Y20: =IF(V20>W20, "è in grado", "non è in grado") -> è in grado | Z20: =IF(R20>10000, "sottende", "non sottende") -> non sottende | AA20: =V20/W20 -> 2.249501 | AB20: =IF(R20>10000, "B", IF(AA20>=2, "A", "B")) -> A | AC20: =IF(O20="di testa rete",IF(V20>W20,"SI","NO"),IF(V20>20,IF(V20>(W20+0.001),"SI","NO"),IF(V20<(W20+0.001),"NO",IF(O20="in testa impianto sollevamento","SI",IF(O20="in testa impianto di depurazione",IF(K20="Ponti sul Mincio (Capoluogo)","NO","SI"),"NO"))))) -> SI | AD20: =IF(V20>20, "Si", "No") -> Si | AE20: non occorre | AF20: 7.31 | AG20: 854 | AH20: 948 | AI20: =IF(AG20>AH20, "Manufatto limitante", " ") | AJ20: 187.58 | AK20: =((MIN(AG20:AH20))-V20)/AJ20 -> 4.4325621 | AL20: =MIN(AG20:AH20)-V20 -> 831.46 | AM20: Non occorre (scarica a lago) | AO20: - | AP20: - | AQ20: - | AR20: - | AS20: - | AT20: -
C21: SF-MN-BRES | E21: =D21&""&$E$1 -> 001B | F21: Dismesso a settembre 24, rifatto su suolo pubblico (SF-MN-LAV) | G21: Mantova | H21: Gambarara | I21: Gambarara - via Brescia | J21: 45.17953, 10.78239 | K21: Mantova | L21: canale Gambarara, recapitante ai Laghi di Mantova | N21: si | O21: in testa impianto sollevamento | P21: 519 | Q21: 7 | R21: =P21+Q21 -> 526 | S21: 1.22 | T21: 0.61 | U21: =T21+S21 -> 1.83 | V21: 30 | W21: 6.09 | X21: =V21/U21 -> 16.393443 | Y21: =IF(V21>W21, "è in grado", "non è in grado") -> è in grado | Z21: =IF(R21>10000, "sottende", "non sottende") -> non sottende | AA21: =V21/W21 -> 4.9261084 | AB21: =IF(R21>10000, "B", IF(AA21>=2, "A", "B")) -> A | AC21: =IF(O21="di testa rete",IF(V21>W21,"SI","NO"),IF(V21>20,IF(V21>(W21+0.001),"SI","NO"),IF(V21<(W21+0.001),"NO",IF(O21="in testa impianto sollevamento","SI",IF(O21="in testa impianto di depurazione",IF(K21="Ponti sul Mincio (Capoluogo)","NO","SI"),"NO"))))) -> SI | AD21: =IF(V21>20, "Si", "No") -> Si | AE21: non occorre | AF21: 32.83 | AG21: 3816 | AH21: 2881 | AI21: =IF(AG21>AH21, "Manufatto limitante", " ") -> Manufatto limitante | AJ21: 152 | AK21: =((MIN(AG21:AH21))-V21)/AJ21 -> 18.756579 | AL21: =MIN(AG21:AH21)-V21 -> 2851 | AM21: Non occorre (scarica a lago) | AO21: - | AP21: - | AQ21: - | AR21: - | AS21: - | AT21: -
C22: SF-MN-CIP2 | E22: =D22&""&$E$1 -> 001B | F22: Dismesso | G22: Mantova | H22: Lunetta | I22: Strada Lunetta / strada Cipata | J22: 45.16145705318603, 10.816036154271155 | K22: Mantova | L22: Cavo San Giorgio, recapitante ai Laghi di Mantova | N22: si | AC22: =IF(O22="di testa rete",IF(V22>W22,"SI","NO"),IF(V22>20,IF(V22>(W22+0.001),"SI","NO"),IF(V22<(W22+0.001),"NO",IF(O22="in testa impianto sollevamento","SI",IF(O22="in testa impianto di depurazione",IF(K22="Ponti sul Mincio (Capoluogo)","NO","SI"),"NO"))))) -> NO | AI22: =IF(AG22>AH22, "Manufatto limitante", " ") | AK22: =((MIN(AG22:AH22))-V22)/AJ22 -> #DIV/0! | AL22: =MIN(AG22:AH22)-V22 -> 0 | AO22: - | AP22: - | AQ22: - | AR22: - | AS22: - | AT22: -
C23: SF-MN-SPA | E23: =D23&""&$E$1 -> 001B | F23: Dismesso, rete convertita in meteorica 2019 | G23: Mantova | H23: Cittadella | I23: str. Montata/via Spalti | J23: 45.173062123889686, 10.792263591297695 | K23: Mantova | L23: Cavo Parcarello | O23: di rete | AC23: =IF(O23="di testa rete",IF(V23>W23,"SI","NO"),IF(V23>20,IF(V23>(W23+0.001),"SI","NO"),IF(V23<(W23+0.001),"NO",IF(O23="in testa impianto sollevamento","SI",IF(O23="in testa impianto di depurazione",IF(K23="Ponti sul Mincio (Capoluogo)","NO","SI"),"NO"))))) -> NO | AI23: =IF(AG23>AH23, "Manufatto limitante", " ") | AK23: =((MIN(AG23:AH23))-V23)/AJ23 -> #DIV/0! | AL23: =MIN(AG23:AH23)-V23 -> 0 | AO23: - | AP23: - | AQ23: - | AR23: - | AS23: - | AT23: -
C24: SF-MTG-FIL | E24: =D24&""&$E$1 -> 001B | F24: Non trovato in fase di rilievo 2021, definito dismesso | G24: Motteggiana | K24: Villa Saviola | U24: =T24+S24 -> 0 | Y24: =IF(V24>W24, "è in grado", "non è in grado") -> non è in grado | Z24: =IF(R24>10000, "sottende", "non sottende") -> non sottende | AA24: =V24/W24 -> #DIV/0! | AB24: =IF(R24>10000, "B", IF(AA24>=2, "A", "B")) -> #DIV/0! | AC24: =IF(O24="di testa rete",IF(V24>W24,"SI","NO"),IF(V24>20,IF(V24>(W24+0.001),"SI","NO"),IF(V24<(W24+0.001),"NO",IF(O24="in testa impianto sollevamento","SI",IF(O24="in testa impianto di depurazione",IF(K24="Ponti sul Mincio (Capoluogo)","NO","SI"),"NO"))))) -> NO | AD24: =IF(V24>20, "Si", "No") -> No | AI24: =IF(AG24>AH24, "Manufatto limitante", " ") | AK24: =((MIN(AG24:AH24))-V24)/AJ24 -> #DIV/0! | AL24: =MIN(AG24:AH24)-V24 -> 0 | AO24: - | AP24: - | AQ24: - | AR24: - | AS24: - | AT24: -
C25: SF-PVC-MATT1 | E25: =D25&""&$E$1 -> 001B | F25: Dismesso aprile 2022 | G25: Borgo Mantovano | H25: Pieve di Coriano | I25: via Matteotti n.12 | J25: 45.033679, 11.109779 | K25: Pieve di Coriano | AC25: =IF(O25="di testa rete",IF(V25>W25,"SI","NO"),IF(V25>20,IF(V25>(W25+0.001),"SI","NO"),IF(V25<(W25+0.001),"NO",IF(O25="in testa impianto sollevamento","SI",IF(O25="in testa impianto di depurazione",IF(K25="Ponti sul Mincio (Capoluogo)","NO","SI"),"NO"))))) -> NO | AL25: =MIN(AG25:AH25)-V25 -> 0 | AO25: lasciato scadere | AP25: n° PD / 131 del 05/02/2018 | AQ25: - | AR25: - | AS25: - | AT25: -
C26: SF-SCH-ROM | E26: =D26&""&$E$1 -> 001B | F26: dismesso 21-03-22 | G26: Schivenoglia | H26: Capoluogo | I26: Via Roma, 6 | J26: 44.992076, 11.075611 | K26: Schivenoglia (Capoluogo) | L26: Redefossi Boline (da fosso intubato) | O26: di rete | P26: 8 | Q26: 0 | R26: =P26+Q26 -> 8 | S26: 0.02 | T26: 0 | U26: =T26+S26 -> 0.02 | V26: 28.2 | W26: 0.07 | X26: =V26/U26 -> 1410 | Y26: =IF(V26>W26, "è in grado", "non è in grado") -> è in grado | Z26: =IF(R26>10000, "sottende", "non sottende") -> non sottende | AA26: =V26/W26 -> 402.85714 | AB26: =IF(R26>10000, "B", IF(AA26>=2, "A", "B")) -> A | AC26: =IF(O26="di testa rete",IF(V26>W26,"SI","NO"),IF(V26>20,IF(V26>(W26+0.001),"SI","NO"),IF(V26<(W26+0.001),"NO",IF(O26="in testa impianto sollevamento","SI",IF(O26="in testa impianto di depurazione",IF(K26="Ponti sul Mincio (Capoluogo)","NO","SI"),"NO"))))) -> SI | AD26: =IF(V26>20, "Si", "No") -> Si | AE26: non occorre | AF26: 0.6 | AG26: 95 | AH26: 210 | AI26: =IF(AG26>AH26, "Manufatto limitante", " ") | AJ26: 201.7 | AK26: =((MIN(AG26:AH26))-V26)/AJ26 -> 0.33118493 | AL26: =MIN(AG26:AH26)-V26 -> 66.8 | AM26: Occorre vasca volano | AO26: 46166 | AP26: PD/575 del 23/05/2022 | AQ26: - | AR26: - | AS26: -
C27: SF-SNG-555 | E27: =D27&""&$E$1 -> 001B | F27: dismesso | G27: San Giorgio Bigarello | H27: Zona Industriale | I27: via dell'Artigianato | J27: 45.16270084501211, 10.853486365430925 | K27: Mantova | L27: Condotto Olmolungo | O27: di rete | P27: 5 | Q27: 0 | R27: =P27+Q27 -> 5 | S27: 0.01 | T27: 0 | U27: =T27+S27 -> 0.01 | V27: 37.69 | W27: 0.04 | X27: =V27/U27 -> 3769 | Y27: =IF(V27>W27, "è in grado", "non è in grado") -> è in grado | Z27: =IF(R27>10000, "sottende", "non sottende") -> non sottende | AA27: =V27/W27 -> 942.25 | AB27: =IF(R27>10000, "B", IF(AA27>=2, "A", "B")) -> A | AC27: =IF(O27="di testa rete",IF(V27>W27,"SI","NO"),IF(V27>20,IF(V27>(W27+0.001),"SI","NO"),IF(V27<(W27+0.001),"NO",IF(O27="in testa impianto sollevamento","SI",IF(O27="in testa impianto di depurazione",IF(K27="Ponti sul Mincio (Capoluogo)","NO","SI"),"NO"))))) -> SI | AD27: =IF(V27>20, "Si", "No") -> Si | AE27: non occorre | AI27: =IF(AG27>AH27, "Manufatto limitante", " ") | AJ27: 93.31 | AK27: =((MIN(AG27:AH27))-V27)/AJ27 -> -0.40392241 | AL27: =MIN(AG27:AH27)-V27 -> -37.69 | AM27: Occorre vasca volano | AO27: - | AP27: - | AQ27: - | AR27: - | AS27: - | AT27: -
C28: SF-SNM-ONE | E28: =D28&""&$E$1 -> 001B | F28: Considerato dismesso, non trovato anche con scavo | G28: San Martino dall' Argine | I28: via Valle Onetta prop. Privata | K28: S. Martino dall’Argine (capoluogo) | AC28: =IF(O28="di testa rete",IF(V28>W28,"SI","NO"),IF(V28>20,IF(V28>(W28+0.001),"SI","NO"),IF(V28<(W28+0.001),"NO",IF(O28="in testa impianto sollevamento","SI",IF(O28="in testa impianto di depurazione",IF(K28="Ponti sul Mincio (Capoluogo)","NO","SI"),"NO"))))) -> NO | AI28: =IF(AG28>AH28, "Manufatto limitante", " ") | AK28: =((MIN(AG28:AH28))-V28)/AJ28 -> #DIV/0! | AL28: =MIN(AG28:AH28)-V28 -> 0 | AP28: PD/1075 del 20/09/2022 | AQ28: - | AR28: - | AS28: - | AT28: -
C29: SF-SRM-GAD | E29: =D29&""&$E$1 -> 001B | F29: Dismesso e convertito in scarico di piovane 2020 | G29: Sermide e Felonica | I29: via Gadda | J29: 45.00132721107914, 11.300598764577936 | K29: Sermide e Felonica (Sermide) | R29: =P29+Q29 -> 0 | U29: =T29+S29 -> 0 | AC29: =IF(O29="di testa rete",IF(V29>W29,"SI","NO"),IF(V29>20,IF(V29>(W29+0.001),"SI","NO"),IF(V29<(W29+0.001),"NO",IF(O29="in testa impianto sollevamento","SI",IF(O29="in testa impianto di depurazione",IF(K29="Ponti sul Mincio (Capoluogo)","NO","SI"),"NO"))))) -> NO | AI29: =IF(AG29>AH29, "Manufatto limitante", " ") | AL29: =MIN(AG29:AH29)-V29 -> 0 | AQ29: - | AR29: -
C30: SF-SZZ-ZZA1 | E30: =D30&""&$E$1 -> 001B | F30: dismesso | G30: Suzzara | H30: Sailetto | J30: 45.02901098905842, 10.752193973146019 | K30: Motteggiana | O30: in testa impianto sollevamento | AC30: =IF(O30="di testa rete",IF(V30>W30,"SI","NO"),IF(V30>20,IF(V30>(W30+0.001),"SI","NO"),IF(V30<(W30+0.001),"NO",IF(O30="in testa impianto sollevamento","SI",IF(O30="in testa impianto di depurazione",IF(K30="Ponti sul Mincio (Capoluogo)","NO","SI"),"NO"))))) -> NO | AI30: =IF(AG30>AH30, "Manufatto limitante", " ") | AK30: =((MIN(AG30:AH30))-V30)/AJ30 -> #DIV/0! | AL30: =MIN(AG30:AH30)-V30 -> 0 | AO30: - | AP30: - | AQ30: - | AR30: - | AS30: - | AT30: -
C31: SF-BGN-ALL1 | D31: - | E31: =D31&""&$E$1 -> -001B | G31: Bagnolo San Vito | H31: San Biagio | I31: Via Allende 4 | J31: 45.0955, 10.84722 | K31: Bagnolo San Vito (Capoluogo) | L31: Allacciante Berla Dolcini Gherardo (scarica attraverso rete meteorica) | M31: tramite condotta meteo | O31: di rete | P31: 29 | Q31: 0 | R31: =P31+Q31 -> 29 | S31: 0.07 | T31: 0 | U31: =T31+S31 -> 0.07 | V31: 59.11 | W31: =MAX(IF(N31="si",R31*1000/86400,R31*750/86400),IF(Q31>=(0.5*P31),(1.5*S31+T31)*2.5,(1.5*S31+T31)*2)) -> 0.25173611 | X31: =V31/U31 -> 844.42857 | Y31: =IF(V31>W31, "è in grado", "non è in grado") -> è in grado | Z31: =IF(R31>10000, "sottende", "non sottende") -> non sottende | AA31: =V31/W31 -> 234.80938 | AB31: =IF(R31>10000, "B", IF(AA31>=2, "A", "B")) -> A | AC31: =IF(O31="di testa rete",IF(V31>W31,"SI","NO"),IF(V31>20,IF(V31>(W31+0.001),"SI","NO"),IF(V31<(W31+0.001),"NO",IF(O31="in testa impianto sollevamento","SI",IF(O31="in testa impianto di depurazione",IF(K31="Ponti sul Mincio (Capoluogo)","NO","SI"),"NO"))))) -> SI | AD31: =IF(V31>20, "Si", "No") -> Si | AE31: non occorre | AF31: 1.36 | AG31: 186 | AH31: 578 | AI31: =IF(AG31>AH31, "Manufatto limitante", " ") | AJ31: 195.02 | AK31: =((MIN(AG31:AH31))-V31)/AJ31 -> 0.65065122 | AL31: =MIN(AG31:AH31)-V31 -> 126.89 | AM31: Occorre vasca volano | AN31: No | AP31: in meteo - chiedere al comune | AQ31: n.a. - rete meteorica in fosso afferente | AR31: n.a. | AS31: -
C32: SF-BGN-ALL2 | D32: - | E32: =D32&""&$E$1 -> -001B | G32: Bagnolo San Vito | H32: San Biagio | I32: Via Allende / Via Giuseppe di Vittorio | J32: 45.095528, 10.847938 | K32: Bagnolo San Vito (Capoluogo) | L32: Allacciante Berla Dolcini Gherardo (scarica attraverso rete meteorica) | M32: tramite condotta meteo | O32: di rete | P32: 37 | Q32: 0 | R32: =P32+Q32 -> 37 | S32: 0.09 | T32: 0 | U32: =T32+S32 -> 0.09 | V32: 41.23 | W32: =MAX(IF(N32="si",R32*1000/86400,R32*750/86400),IF(Q32>=(0.5*P32),(1.5*S32+T32)*2.5,(1.5*S32+T32)*2)) -> 0.32118056 | X32: =V32/U32 -> 458.11111 | Y32: =IF(V32>W32, "è in grado", "non è in grado") -> è in grado | Z32: =IF(R32>10000, "sottende", "non sottende") -> non sottende | AA32: =V32/W32 -> 128.37016 | AB32: =IF(R32>10000, "B", IF(AA32>=2, "A", "B")) -> A | AC32: =IF(O32="di testa rete",IF(V32>W32,"SI","NO"),IF(V32>20,IF(V32>(W32+0.001),"SI","NO"),IF(V32<(W32+0.001),"NO",IF(O32="in testa impianto sollevamento","SI",IF(O32="in testa impianto di depurazione",IF(K32="Ponti sul Mincio (Capoluogo)","NO","SI"),"NO"))))) -> SI | AD32: =IF(V32>20, "Si", "No") -> Si | AE32: non occorre | AF32: 0.35 | AG32: 110 | AH32: 405 | AI32: =IF(AG32>AH32, "Manufatto limitante", " ") | AJ32: 394.28 | AK32: =((MIN(AG32:AH32))-V32)/AJ32 -> 0.17441919 | AL32: =MIN(AG32:AH32)-V32 -> 68.77 | AM32: Occorre vasca volano | AN32: No | AP32: in meteo - chiedere al comune | AQ32: n.a. - rete meteorica in fosso afferente | AR32: n.a. | AS32: -
C33: SF-BGN-BAI | D33: PP0200030014 | E33: =D33&""&$E$1 -> PP0200030014001B | G33: Bagnolo San Vito | H33: San Nicolò Po | I33: Via Baiona (dopo Via Papa Giovanni XXIII) | J33: 45.053653, 10.832636 | K33: Bagnolo San Vito (S. Nicolò Po) | L33: Canale Dugaletto | O33: in testa impianto di depurazione | P33: 317 | Q33: 0 | R33: =P33+Q33 -> 317 | S33: 0.75 | T33: 0 | U33: =T33+S33 -> 0.75 | V33: 10 | W33: =MAX(IF(N33="si",R33*1000/86400,R33*750/86400),IF(Q33>=(0.5*P33),(1.5*S33+T33)*2.5,(1.5*S33+T33)*2)) -> 2.7517361 | X33: =V33/U33 -> 13.333333 | Y33: =IF(V33>W33, "è in grado", "non è in grado") -> è in grado | Z33: =IF(R33>10000, "sottende", "non sottende") -> non sottende | AA33: =V33/W33 -> 3.6340694 | AB33: =IF(R33>10000, "B", IF(AA33>=2, "A", "B")) -> A | AC33: =IF(O33="di testa rete",IF(V33>W33,"SI","NO"),IF(V33>20,IF(V33>(W33+0.001),"SI","NO"),IF(V33<(W33+0.001),"NO",IF(O33="in testa impianto sollevamento","SI",IF(O33="in testa impianto di depurazione",IF(K33="Ponti sul Mincio (Capoluogo)","NO","SI"),"NO"))))) -> SI | AD33: =IF(V33>20, "Si", "No") -> No | AE33: non occorre | AF33: 15.47 | AG33: 1563 | AH33: 2595 | AI33: =IF(AG33>AH33, "Manufatto limitante", " ") | AJ33: 190.98 | AK33: =((MIN(AG33:AH33))-V33)/AJ33 -> 8.1317415 | AL33: =MIN(AG33:AH33)-V33 -> 1553 | AM33: Occorre vasca volano | AN33: Si | AO33: 46880 | AP33: n° PD / 722 del 03/05/2024 | AQ33: TDM | AR33: IN CORSO | AS33: Richiesta in data 3/05/2023
C34: SF-BGN-BGN | D34: PP0200030006 | E34: =D34&""&$E$1 -> PP0200030006001B | G34: Bagnolo San Vito | H34: Capoluogo | I34: Via Virgiliana (accesso) | J34: 45.09311, 10.875454 | K34: Bagnolo San Vito (Capoluogo) | L34: Cavo Franzina | O34: di rete | P34: 703 | Q34: 0 | R34: =P34+Q34 -> 703 | S34: 1.65 | T34: 0 | U34: =T34+S34 -> 1.65 | V34: 182.2 | W34: =MAX(IF(N34="si",R34*1000/86400,R34*750/86400),IF(Q34>=(0.5*P34),(1.5*S34+T34)*2.5,(1.5*S34+T34)*2)) -> 6.1024306 | X34: =V34/U34 -> 110.42424 | Y34: =IF(V34>W34, "è in grado", "non è in grado") -> è in grado | Z34: =IF(R34>10000, "sottende", "non sottende") -> non sottende | AA34: =V34/W34 -> 29.856956 | AB34: =IF(R34>10000, "B", IF(AA34>=2, "A", "B")) -> A | AC34: =IF(O34="di testa rete",IF(V34>W34,"SI","NO"),IF(V34>20,IF(V34>(W34+0.001),"SI","NO"),IF(V34<(W34+0.001),"NO",IF(O34="in testa impianto sollevamento","SI",IF(O34="in testa impianto di depurazione",IF(K34="Ponti sul Mincio (Capoluogo)","NO","SI"),"NO"))))) -> SI | AD34: =IF(V34>20, "Si", "No") -> Si | AE34: non occorre | AF34: 19.09 | AG34: 1704 | AH34: 1913 | AI34: =IF(AG34>AH34, "Manufatto limitante", " ") | AJ34: 168.36 | AK34: =((MIN(AG34:AH34))-V34)/AJ34 -> 9.0389641 | AL34: =MIN(AG34:AH34)-V34 -> 1521.8 | AM34: Occorre vasca volano | AN34: Si | AO34: 46719 | AP34: n° PD / 1957 28/11/2023 | AQ34: TDM | AR34: IN CORSO | AT34: Richiesta in data 31.01.2023
C35: SF-BGN-CAM1 | D35: PP0200030001 | E35: =D35&""&$E$1 -> PP0200030001001B | G35: Bagnolo San Vito | H35: Campione | I35: Via Campione 31/c | J35: 45.081287936122656, 10.820213494883854 | K35: Bagnolo san Vito (Campione) | L35: Gasparola tramite fossato di scolo | O35: di testa rete | P35: 144 | Q35: 0 | R35: =P35+Q35 -> 144 | S35: 0.34 | T35: 0 | U35: =T35+S35 -> 0.34 | V35: 10.5 | W35: =MAX(IF(N35="si",R35*1000/86400,R35*750/86400),IF(Q35>=(0.5*P35),(1.5*S35+T35)*2.5,(1.5*S35+T35)*2)) -> 1.25 | X35: =V35/U35 -> 30.882353 | Y35: =IF(V35>W35, "è in grado", "non è in grado") -> è in grado | Z35: =IF(R35>10000, "sottende", "non sottende") -> non sottende | AA35: =V35/W35 -> 8.4 | AB35: =IF(R35>10000, "B", IF(AA35>=2, "A", "B")) -> A | AC35: =IF(O35="di testa rete",IF(V35>W35,"SI","NO"),IF(V35>20,IF(V35>(W35+0.001),"SI","NO"),IF(V35<(W35+0.001),"NO",IF(O35="in testa impianto sollevamento","SI",IF(O35="in testa impianto di depurazione",IF(K35="Ponti sul Mincio (Capoluogo)","NO","SI"),"NO"))))) -> SI | AD35: =IF(V35>20, "Si", "No") -> No | AE35: non occorre | AF35: 8.42 | AG35: 900 | AH35: 935.7 | AI35: =IF(AG35>AH35, "Manufatto limitante", " ") | AJ35: 220.2 | AK35: =((MIN(AG35:AH35))-V35)/AJ35 -> 4.0395095 | AL35: =MIN(AG35:AH35)-V35 -> 889.5 | AM35: Occorre vasca volano | AN35: No | AO35: 46685 | AP35: n° PD / 1786 24/10/2023 | AQ35: fosso privato afferente canale consortile - n.a. | AR35: n.a. | AS35: -
C36: SF-BGN-CHI | D36: PP0200030003 | E36: =D36&""&$E$1 -> PP0200030003001B | F36: Relazione incompleta, manca Qs | G36: Bagnolo San Vito | H36: San Biagio | I36: via Chiesa | J36: 45.099066, 10.8501 | K36: Bagnolo San Vito (Capoluogo) | L36: Canale Fossetta | O36: di rete | P36: 35 | Q36: 0 | R36: =P36+Q36 -> 35 | S36: 0.08 | T36: 0 | U36: =T36+S36 -> 0.08 | V36: 29.96 | W36: =MAX(IF(N36="si",R36*1000/86400,R36*750/86400),IF(Q36>=(0.5*P36),(1.5*S36+T36)*2.5,(1.5*S36+T36)*2)) -> 0.30381944 | X36: =V36/U36 -> 374.5 | Y36: =IF(V36>W36, "è in grado", "non è in grado") -> è in grado | Z36: =IF(R36>10000, "sottende", "non sottende") -> non sottende | AA36: =V36/W36 -> 98.6112 | AB36: =IF(R36>10000, "B", IF(AA36>=2, "A", "B")) -> A | AC36: =IF(O36="di testa rete",IF(V36>W36,"SI","NO"),IF(V36>20,IF(V36>(W36+0.001),"SI","NO"),IF(V36<(W36+0.001),"NO",IF(O36="in testa impianto sollevamento","SI",IF(O36="in testa impianto di depurazione",IF(K36="Ponti sul Mincio (Capoluogo)","NO","SI"),"NO"))))) -> SI | AD36: =IF(V36>20, "Si", "No") -> Si | AE36: non occorre | AF36: 1.34 | AG36: 167 | AH36: 1067 | AI36: =IF(AG36>AH36, "Manufatto limitante", " ") | AJ36: 231 | AK36: =((MIN(AG36:AH36))-V36)/AJ36 -> 0.59324675 | AL36: =MIN(AG36:AH36)-V36 -> 137.04 | AM36: Occorre vasca volano | AN36: No | AO36: 46719 | AP36: n° PD / 1957 28/11/2023 | AQ36: TDM | AR36: IN CORSO | AT36: Richiesta in data 31.01.2023
C37: SF-BGN-FER1 | D37: - | E37: =D37&""&$E$1 -> -001B | G37: Bagnolo San Vito | H37: San Biagio | I37: via Ferri 9 | J37: 45.094512, 10.847054 | K37: Bagnolo San Vito (Capoluogo) | L37: Allacciante Berla Dolcini Gherardo (scarica attraverso rete meteorica) | M37: tramite condotta meteo | O37: di rete | P37: 34 | Q37: 0 | R37: =P37+Q37 -> 34 | S37: 0.08 | T37: 0 | U37: =T37+S37 -> 0.08 | V37: 43.32 | W37: =MAX(IF(N37="si",R37*1000/86400,R37*750/86400),IF(Q37>=(0.5*P37),(1.5*S37+T37)*2.5,(1.5*S37+T37)*2)) -> 0.29513889 | X37: =V37/U37 -> 541.5 | Y37: =IF(V37>W37, "è in grado", "non è in grado") -> è in grado | Z37: =IF(R37>10000, "sottende", "non sottende") -> non sottende | AA37: =V37/W37 -> 146.77835 | AB37: =IF(R37>10000, "B", IF(AA37>=2, "A", "B")) -> A | AC37: =IF(O37="di testa rete",IF(V37>W37,"SI","NO"),IF(V37>20,IF(V37>(W37+0.001),"SI","NO"),IF(V37<(W37+0.001),"NO",IF(O37="in testa impianto sollevamento","SI",IF(O37="in testa impianto di depurazione",IF(K37="Ponti sul Mincio (Capoluogo)","NO","SI"),"NO"))))) -> SI | AD37: =IF(V37>20, "Si", "No") -> Si | AE37: non occorre | AF37: 1.18 | AG37: 187 | AH37: 536 | AI37: =IF(AG37>AH37, "Manufatto limitante", " ") | AJ37: 220.37 | AK37: =((MIN(AG37:AH37))-V37)/AJ37 -> 0.65199437 | AL37: =MIN(AG37:AH37)-V37 -> 143.68 | AM37: Occorre vasca volano | AN37: No | AP37: in meteo - chiedere al comune | AQ37: n.a. - rete meteorica in fosso afferente | AR37: n.a. | AS37: -
C38: SF-BGN-FER2 | D38: - | E38: =D38&""&$E$1 -> -001B | G38: Bagnolo San Vito | H38: San Biagio | I38: via Ferri 3 | J38: 45.09424, 10.84772 | K38: Bagnolo San Vito (Capoluogo) | L38: Allacciante Berla Dolcini Gherardo (scarica attraverso rete meteorica) | M38: tramite condotta meteo | O38: di rete | P38: 107 | Q38: 0 | R38: =P38+Q38 -> 107 | S38: 0.25 | T38: 0 | U38: =T38+S38 -> 0.25 | V38: 31.37 | W38: =MAX(IF(N38="si",R38*1000/86400,R38*750/86400),IF(Q38>=(0.5*P38),(1.5*S38+T38)*2.5,(1.5*S38+T38)*2)) -> 0.92881944 | X38: =V38/U38 -> 125.48 | Y38: =IF(V38>W38, "è in grado", "non è in grado") -> è in grado | Z38: =IF(R38>10000, "sottende", "non sottende") -> non sottende | AA38: =V38/W38 -> 33.774056 | AB38: =IF(R38>10000, "B", IF(AA38>=2, "A", "B")) -> A | AC38: =IF(O38="di testa rete",IF(V38>W38,"SI","NO"),IF(V38>20,IF(V38>(W38+0.001),"SI","NO"),IF(V38<(W38+0.001),"NO",IF(O38="in testa impianto sollevamento","SI",IF(O38="in testa impianto di depurazione",IF(K38="Ponti sul Mincio (Capoluogo)","NO","SI"),"NO"))))) -> SI | AD38: =IF(V38>20, "Si", "No") -> Si | AE38: non occorre | AF38: 0.99 | AG38: 224 | AH38: 566 | AI38: =IF(AG38>AH38, "Manufatto limitante", " ") | AJ38: 369.93 | AK38: =((MIN(AG38:AH38))-V38)/AJ38 -> 0.52072014 | AL38: =MIN(AG38:AH38)-V38 -> 192.63 | AM38: Occorre vasca volano | AN38: No | AP38: in meteo - chiedere al comune | AQ38: n.a. - rete meteorica in fosso afferente | AR38: n.a. | AS38: -
C39: SF-BGN-FER3 | D39: - | E39: =D39&""&$E$1 -> -001B | G39: Bagnolo San Vito | H39: San Biagio | I39: via Ferri | J39: 45.094025, 10.848405 | K39: Bagnolo San Vito (Capoluogo) | L39: Allacciante Berla Dolcini Gherardo (scarica attraverso rete meteorica) | M39: tramite condotta meteo | O39: di rete | P39: 128 | Q39: 0 | R39: =P39+Q39 -> 128 | S39: 0.3 | T39: 0 | U39: =T39+S39 -> 0.3 | V39: 64.39 | W39: =MAX(IF(N39="si",R39*1000/86400,R39*750/86400),IF(Q39>=(0.5*P39),(1.5*S39+T39)*2.5,(1.5*S39+T39)*2)) -> 1.1111111 | X39: =V39/U39 -> 214.63333 | Y39: =IF(V39>W39, "è in grado", "non è in grado") -> è in grado | Z39: =IF(R39>10000, "sottende", "non sottende") -> non sottende | AA39: =V39/W39 -> 57.951 | AB39: =IF(R39>10000, "B", IF(AA39>=2, "A", "B")) -> A | AC39: =IF(O39="di testa rete",IF(V39>W39,"SI","NO"),IF(V39>20,IF(V39>(W39+0.001),"SI","NO"),IF(V39<(W39+0.001),"NO",IF(O39="in testa impianto sollevamento","SI",IF(O39="in testa impianto di depurazione",IF(K39="Ponti sul Mincio (Capoluogo)","NO","SI"),"NO"))))) -> SI | AD39: =IF(V39>20, "Si", "No") -> Si | AE39: non occorre | AF39: 0.73 | AG39: 149 | AH39: 533 | AI39: =IF(AG39>AH39, "Manufatto limitante", " ") | AJ39: 210.55 | AK39: =((MIN(AG39:AH39))-V39)/AJ39 -> 0.40185229 | AL39: =MIN(AG39:AH39)-V39 -> 84.61 | AM39: Occorre vasca volano | AN39: No | AP39: in meteo - chiedere al comune | AQ39: n.a. - rete meteorica in fosso afferente | AR39: n.a. | AS39: -
C40: SF-BGN-GAS | D40: PP0200030013 | E40: =D40&""&$E$1 -> PP0200030013001B | G40: Bagnolo San Vito | H40: San Giacomo Po | I40: Via De Gasperi | J40: 45.072436, 10.874688 | K40: Bagnolo San Vito (Capoluogo) | L40: Canale Bolognina | O40: in testa impianto sollevamento | P40: 411 | Q40: 0 | R40: =P40+Q40 -> 411 | S40: 0.97 | T40: 0 | U40: =T40+S40 -> 0.97 | V40: 9 | W40: =MAX(IF(N40="si",R40*1000/86400,R40*750/86400),IF(Q40>=(0.5*P40),(1.5*S40+T40)*2.5,(1.5*S40+T40)*2)) -> 3.5677083 | X40: =V40/U40 -> 9.2783505 | Y40: =IF(V40>W40, "è in grado", "non è in grado") -> è in grado | Z40: =IF(R40>10000, "sottende", "non sottende") -> non sottende | AA40: =V40/W40 -> 2.5226277 | AB40: =IF(R40>10000, "B", IF(AA40>=2, "A", "B")) -> A | AC40: =IF(O40="di testa rete",IF(V40>W40,"SI","NO"),IF(V40>20,IF(V40>(W40+0.001),"SI","NO"),IF(V40<(W40+0.001),"NO",IF(O40="in testa impianto sollevamento","SI",IF(O40="in testa impianto di depurazione",IF(K40="Ponti sul Mincio (Capoluogo)","NO","SI"),"NO"))))) -> SI | AD40: =IF(V40>20, "Si", "No") -> No | AE40: non occorre | AF40: 5.62 | AG40: 320 | AH40: 668 | AI40: =IF(AG40>AH40, "Manufatto limitante", " ") | AJ40: 180.65 | AK40: =((MIN(AG40:AH40))-V40)/AJ40 -> 1.721561 | AL40: =MIN(AG40:AH40)-V40 -> 311 | AM40: Occorre vasca volano | AN40: Si | AO40: 46719 | AP40: n° PD / 1957 28/11/2023 | AQ40: TDM | AR40: IN CORSO | AT40: Richiesta in data 31.01.2023
...

Sheet AIMAG
B1: Codice | C1: Cod Prov Manufa SF | D1: Cod Prov Scarico SF | E1: Note | F1: COMUNE | G1: LOCALITA | H1: UBICAZIONE | I1: Coordinate | J1: DEPURATORE ASSOCIATO | K1: RECAPITO EMISSARIO | L1: Tipo di scarico | M1: Scarica a lago o suolo? (serve per il calcolo automatico di Pavv) | N1: TIPO | O1: AE CIV | P1: AE IND | Q1: AE TOT | R1: Q CIV [l/s] | S1: Q IND [l/s] | T1: Qnm [l/s] | U1: Qs [l/s] | V1: Pavv [l/s] | W1: Qs/Qnm | X1: Qs > Pavv | Y1: 10'000 AE | Z1: Qs/Pavv | AA1: TIPOLOGIA | AB1: è conforme? | AC1: Qs>20 | AD1: Vasca RR | AE1: Bacino proprio (ha) | AF1: Q meteo in ingresso al manufatto (l/s) | AG1: Q limite ingresso al manufatto (l/s) | AH1: Manufatto limitante | AI1: Portata specifica allo scarico [l/s haimp] | AJ1: Sup imp [ha] | AK1: Qscolmata [l/s] | AL1: Vasca PTUA | AM1: Scadenza autorizzazione Provincia | AN1: Atto Provincia n° | AO1: Consorzio competente | AP1: Scadenza concessione Consorzio | AQ1: Atto Consorzio n° | AR1: Note AUT./CONC.
C2: PP0200350001 | D2: =C2&""&'Tabella riassuntiva'!$E$1 -> PP0200350001001B | F2: Moglia | H2: SP50 Suzzara-Moglia | J2: MOGLIA | K2: fosso collegato canale Ceriaga Margonazza | AM2: 2029 | AN2: ATTO DIRIGENZIALE n° PD / 356 del 28/02/2025 | AO2: Gonzaga in dx Po
C3: PP0200350002 | D3: =C3&""&'Tabella riassuntiva'!$E$1 -> PP0200350002001B | F3: Moglia | H3: via IV Novembre | J3: MOGLIA | K3: Fosso collegato al canale Magnariso | AM3: 2029 | AN3: ATTO DIRIGENZIALE n° PD / 356 del 28/02/2025 | AO3: Gonzaga in dx Po
C4: PP0200350004 | D4: =C4&""&'Tabella riassuntiva'!$E$1 -> PP0200350004001B | F4: Moglia | H4: Via Lunga | J4: MOGLIA | K4: Canale Via Lunga | AM4: 2029 | AN4: ATTO DIRIGENZIALE n° PD / 356 del 28/02/2025 | AO4: Gonzaga in dx Po
C5: PP0200350006 | D5: =C5&""&'Tabella riassuntiva'!$E$1 -> PP0200350006001B | F5: Moglia | H5: via Tangenziale Nord | J5: MOGLIA | K5: Fosso collegato al canale Ceriaga-Margonazza | AM5: 2029 | AN5: ATTO DIRIGENZIALE n° PD / 356 del 28/02/2025 | AO5: Gonzaga in dx Po
C6: PP0200350007 | D6: =C6&""&'Tabella riassuntiva'!$E$1 -> PP0200350007001B | F6: Moglia | H6: via Tangenziale Nord | J6: MOGLIA | K6: Fosso collegato al canale Ceriaga-Margonazza | AM6: 2029 | AN6: ATTO DIRIGENZIALE n° PD / 356 del 28/02/2025 | AO6: Gonzaga in dx Po
C7: PP0200350010 | D7: =C7&""&'Tabella riassuntiva'!$E$1 -> PP0200350010001B | F7: Moglia | H7: Via U. Foscolo | J7: MOGLIA | K7: Canale collegato allo scolo Busatello Vecchio | AM7: 2029 | AN7: ATTO DIRIGENZIALE n° PD / 356 del 28/02/2025 | AO7: Gonzaga in dx Po
C8: PP0200350012 | D8: =C8&""&'Tabella riassuntiva'!$E$1 -> PP0200350012001B | F8: Moglia | H8: Via Lunga incrocio Via IV Novembre | J8: MOGLIA | K8: Canale Via Lunga | AM8: 2029 | AN8: ATTO DIRIGENZIALE n° PD / 356 del 28/02/2025 | AO8: Gonzaga in dx Po
C9: PP0200350011 | D9: =C9&""&'Tabella riassuntiva'!$E$1 -> PP0200350011001B | F9: Moglia | H9: Via Lunga incrocio Via Michelangelo | J9: MOGLIA | K9: Canale Via Lunga | AM9: 2029 | AN9: ATTO DIRIGENZIALE n° PD / 356 del 28/02/2025 | AO9: Gonzaga in dx Po
C10: PP0200350003 | D10: =C10&""&'Tabella riassuntiva'!$E$1 -> PP0200350003001B | F10: Moglia | G10: Bondanello | H10: via Trivellano | J10: BONDANELLO | K10: Canale Bondanello | AM10: 2028 | AN10: ATTO DIRIGENZIALE n° PD / 490 del 26/03/2024 | AO10: Gonzaga in dx Po
C11: PP0200350005 | D11: =C11&""&'Tabella riassuntiva'!$E$1 -> PP0200350005001B | F11: Moglia | G11: Bondanello | H11: via Coazze | J11: BONDANELLO | K11: Canale Bondanello | AM11: 2028 | AN11: ATTO DIRIGENZIALE n° PD / 490 del 26/03/2024 | AO11: Gonzaga in dx Po
C12: PP0200350008 | D12: =C12&""&'Tabella riassuntiva'!$E$1 -> PP0200350008001B | F12: Moglia | G12: Bondanello | H12: incrocio tra via IV Novembre e via Pertini | J12: BONDANELLO | K12: scolina stradale in fregio a via IV Novembre | AM12: 2028 | AN12: ATTO DIRIGENZIALE n° PD / 490 del 26/03/2024 | AO12: Gonzaga in dx Po
B13: MOG-SC-09 | C13: - | D13: =C13&""&'Tabella riassuntiva'!$E$1 -> -001B | F13: Moglia | H13: via de amicis N.9 | J13: MOGLIA | K13: Canale collegato al cavo Busatello Vecchio tramite condotta meteo | L13: condotta meteo | AO13: Gonzaga in dx Po
C14: PP0200580001 | D14: =C14&""&'Tabella riassuntiva'!$E$1 -> PP0200580001001B | F14: San Giovanni del Dosso | H14: Via Roma c/o ex depuratore di San Giovanni del Dosso | J14: POGGIO RUSCO | K14: Fossetta delle Pietre | AM14: 2028 | AN14: ATTO DIRIGENZIALE n° PD / 414 del 08/03/2024 | AO14: BURANA | AP14: 2024 | AQ14: 7597/94 | AR14: rilasciato al comune
C15: PP0200580002 | D15: =C15&""&'Tabella riassuntiva'!$E$1 -> PP0200580002001B | F15: San Giovanni del Dosso | H15: Via D. Dossi | J15: POGGIO RUSCO | K15: Fossetta delle Pietre | AM15: 2028 | AN15: ATTO DIRIGENZIALE n° PD / 414 del 08/03/2024
C16: PP0200420014 | D16: =C16&""&'Tabella riassuntiva'!$E$1 -> PP0200420014001B | F16: Poggio Rusco | G16: loc. La Montata | H16: loc. La Montata | J16: POGGIO RUSCO | K16: Dugale Vangadizza | AM16: 2028 | AN16: ATTO DIRIGENZIALE n° PD / 414 del 08/03/2024
C17: PP0200420003 | D17: =C17&""&'Tabella riassuntiva'!$E$1 -> PP0200420003001B | F17: Poggio Rusco | H17: Via Abetone Brennero | J17: POGGIO RUSCO | K17: Fossetta Piva | AM17: 2028 | AN17: ATTO DIRIGENZIALE n° PD / 414 del 08/03/2024
C18: PP0200420011 | D18: =C18&""&'Tabella riassuntiva'!$E$1 -> PP0200420011001B | F18: Poggio Rusco | H18: Via Martiri della Libertà | J18: POGGIO RUSCO | K18: Fossetta Piva | AM18: 2028 | AN18: ATTO DIRIGENZIALE n° PD / 414 del 08/03/2024 | AO18: BURANA | AQ18: 13773/2023
C19: PP0200420010 | D19: =C19&""&'Tabella riassuntiva'!$E$1 -> PP0200420010001B | F19: Poggio Rusco | H19: Via G. Garibaldi incrocio Via Torino | J19: POGGIO RUSCO | K19: Fossetta Piva | AM19: 2028 | AN19: ATTO DIRIGENZIALE n° PD / 414 del 08/03/2024 | AO19: BURANA | AQ19: 10038/2020
C20: PP0200420009 | D20: =C20&""&'Tabella riassuntiva'!$E$1 -> PP0200420009001B | F20: Poggio Rusco | H20: Via L. Einaudi | J20: POGGIO RUSCO | K20: Fosso Verdonda | AM20: 2028 | AN20: ATTO DIRIGENZIALE n° PD / 414 del 08/03/2024 | AO20: BURANA | AQ20: 7971/2020
C21: PP0200420006 | D21: =C21&""&'Tabella riassuntiva'!$E$1 -> PP0200420006001B | F21: Poggio Rusco | H21: Via Carnevale | J21: POGGIO RUSCO | K21: Fosso Verdonda | AM21: 2028 | AN21: ATTO DIRIGENZIALE n° PD / 414 del 08/03/2024 | AO21: BURANA | AQ21: 7972/2020
C22: PP0200420004 | D22: =C22&""&'Tabella riassuntiva'!$E$1 -> PP0200420004001B | F22: Poggio Rusco | H22: Via Bastiglia | J22: POGGIO RUSCO | K22: Fossa Nasina | AM22: 2028 | AN22: ATTO DIRIGENZIALE n° PD / 414 del 08/03/2024 | AO22: BURANA | AQ22: 13772/2023
C23: PP0200420016 | D23: =C23&""&'Tabella riassuntiva'!$E$1 -> PP0200420016001B | F23: Poggio Rusco | G23: loc. Pinzone | H23: c/o ex depuratore in Via Pinzone | J23: POGGIO RUSCO | K23: Fossa Nasina | AM23: 2028 | AN23: ATTO DIRIGENZIALE n° PD / 414 del 08/03/2024 | AO23: BURANA | AQ23: 13790/2023
C24: PP0200420015 | D24: =C24&""&'Tabella riassuntiva'!$E$1 -> PP0200420015001B | F24: Poggio Rusco | G24: loc. Pinzone | H24: Via Pinzone | J24: POGGIO RUSCO | K24: Fossa Nasina | AM24: 2028 | AN24: ATTO DIRIGENZIALE n° PD / 414 del 08/03/2024 | AO24: BURANA | AQ24: 13790/2023
C25: PP0200420008 | D25: =C25&""&'Tabella riassuntiva'!$E$1 -> PP0200420008001B | F25: Poggio Rusco | H25: Via del Lavoro incrocio S.S. 12 | J25: POGGIO RUSCO | K25: Fossetta Piva | AM25: 2028 | AN25: ATTO DIRIGENZIALE n° PD / 414 del 08/03/2024 | AO25: BURANA | AQ25: 13786/2023
C26: PP0200420007 | D26: =C26&""&'Tabella riassuntiva'!$E$1 -> PP0200420007001B | F26: Poggio Rusco | H26: Via del Lavoro | J26: POGGIO RUSCO | K26: Fosso Verdonda | AM26: 2028 | AN26: ATTO DIRIGENZIALE n° PD / 414 del 08/03/2024 | AO26: BURANA | AQ26: 10039/2020
C27: PP0200420001 | D27: =C27&""&'Tabella riassuntiva'!$E$1 -> PP0200420001001B | F27: Poggio Rusco | H27: Via Quattrocase | J27: POGGIO RUSCO | K27: Dugale Vangadizza | AM27: 2028 | AN27: ATTO DIRIGENZIALE n° PD / 414 del 08/03/2024 | AO27: BURANA | AQ27: 10710/03 /o 10037/2020 | AR27: quale è quella giusta
C28: PP0200420005 | D28: =C28&""&'Tabella riassuntiva'!$E$1 -> PP0200420005001B | F28: Poggio Rusco | H28: Via Borgo | J28: POGGIO RUSCO | K28: Dugale Vangadizza | AM28: 2028 | AN28: ATTO DIRIGENZIALE n° PD / 414 del 08/03/2024 | AO28: BURANA | AQ28: 13787/2023
C29: PP0200420002 | D29: =C29&""&'Tabella riassuntiva'!$E$1 -> PP0200420002001B | F29: Poggio Rusco | H29: Via G. Galilei, incrocio con Via Abetone Brennero | J29: POGGIO RUSCO | K29: Fossetta delle Pietre | AM29: 2028 | AN29: ATTO DIRIGENZIALE n° PD / 414 del 08/03/2024
C30: PP0200420017 | D30: =C30&""&'Tabella riassuntiva'!$E$1 -> PP0200420017001B | F30: Poggio Rusco | H30: Via T. Massarani | J30: POGGIO RUSCO | K30: Fossetta delle Pietre | AM30: 2028 | AN30: ATTO DIRIGENZIALE n° PD / 414 del 08/03/2024
B31: SGD-SC-03 | C31: - | D31: =C31&""&'Tabella riassuntiva'!$E$1 -> -001B | F31: San Giovanni del Dosso | H31: via San Giovanni del Dosso | J31: POGGIO RUSCO | K31: Fossetta delle Pietre tramite condotta meteo | L31: condotta meteo | M31: condotta meteo | N31: condotta meteo | O31: condotta meteo | P31: condotta meteo | Q31: condotta meteo | R31: condotta meteo | S31: condotta meteo | T31: condotta meteo | U31: condotta meteo | V31: condotta meteo | W31: condotta meteo | X31: condotta meteo | Y31: condotta meteo | Z31: condotta meteo | AA31: condotta meteo | AB31: condotta meteo | AC31: condotta meteo | AD31: condotta meteo | AE31: condotta meteo | AF31: condotta meteo | AG31: condotta meteo | AH31: condotta meteo | AI31: condotta meteo | AJ31: condotta meteo | AK31: condotta meteo | AL31: condotta meteo
C32: PP0200420013 | D32: =C32&""&'Tabella riassuntiva'!$E$1 -> PP0200420013001B | F32: Poggio Rusco | G32: loc. Drangoncello | H32: via stoppiaro | J32: DRANGONCELLO | K32: Cavettino Dragoncello | AM32: 2027 | AN32: ATTO DIRIGENZIALE n° PD / 2090 del 19/12/2023 | AO32: BURANA | AQ32: 7968/2020
C33: PP0200420012 | D33: =C33&""&'Tabella riassuntiva'!$E$1 -> PP0200420012001B | F33: Poggio Rusco | H33: via stoppiaro | J33: DRANGONCELLO | K33: Cavettino Dragoncello | AM33: 2027 | AN33: ATTO DIRIGENZIALE n° PD / 2090 del 19/12/2023 | AO33: BURANA | AQ33: 7970/2020
C34: PP0200730002 | D34: =C34&""&'Tabella riassuntiva'!$E$1 -> PP0200730002001B | F34: Borgofranco sul Po | H34: via Bancare Seconda Traversa | J34: REVERE | K34: Redefossi Bancare | AM34: 2028 | AN34: ATTO DIRIGENZIALE n° PD 1971 del 30/11/2023 | AO34: Gonzaga in dx Po | AQ34: Prot. n° 3038 Anno 2023
C35: PP0200720001 | D35: =C35&""&'Tabella riassuntiva'!$E$1 -> PP0200720001001B | F35: Borgofranco sul Po | G35: loc. Bonizzo | H35: Via Casoni | J35: REVERE | K35: Dugale Redefossi 1° | AM35: 2028 | AN35: ATTO DIRIGENZIALE n° PD 1971 del 30/11/2023 | AO35: Gonzaga in dx Po | AQ35: Prot. n° 3023 Anno 2023
C36: PP0200720004 | D36: =C36&""&'Tabella riassuntiva'!$E$1 -> PP0200720004001B | F36: Borgo Mantovano | H36: via U. Foscolo | J36: REVERE | K36: Dugale Lavacollo | AM36: 2028 | AN36: ATTO DIRIGENZIALE n° PD 1971 del 30/11/2023 | AO36: Gonzaga in dx Po | AQ36: Prot. n° 3008 Anno 2023 | AR36: esiste un atto di AIMAG che chiede rimozione della concessione perchè è stato dismesso
C37: PP0200720005 | D37: =C37&""&'Tabella riassuntiva'!$E$1 -> PP0200720005001B | F37: Borgo Mantovano | H37: via G. di Vittorio | J37: REVERE | K37: Dugale Lavacollo | L37: testa impianto | AM37: 2028 | AN37: ATTO DIRIGENZIALE n° PD 1971 del 30/11/2023 | AO37: Gonzaga in dx Po | AQ37: Prot. n° 3002 Anno 2023
C38: PP0200720009 | D38: =C38&""&'Tabella riassuntiva'!$E$1 -> PP0200720009001B | F38: Borgo Mantovano | H38: via G. di Vittorio | J38: REVERE | K38: Dugale Lavacollo | AM38: 2028 | AN38: ATTO DIRIGENZIALE n° PD 1971 del 30/11/2023
C39: PP0200720010 | D39: =C39&""&'Tabella riassuntiva'!$E$1 -> PP0200720010001B | F39: Borgo Mantovano | H39: via G. Rossa | J39: REVERE | K39: Dugale Lavacollo | AM39: 2028 | AN39: ATTO DIRIGENZIALE n° PD 1971 del 30/11/2023 | AO39: Gonzaga in dx Po | AQ39: 0826/17 rep 591
B40: BOR-SC-03 | C40: - | D40: =C40&""&'Tabella riassuntiva'!$E$1 -> -001B | F40: Borgo Mantovano | H40: incrocio fra via Virgilio e via Don Ferrari | J40: REVERE | K40: Dugale Redefossi | L40: condotta meteo
...

Sheet SFIORI SCADUTI
B1: Inadempienza provincia - chidere info | G1: PRIORITà ENTRO MARZ0/APRILE DECISA CON PAOLA MARAZZOLI
B2: Inadempienza nostra- mandare avanti richiesta
B3: Da capire
B5: Codice | C5: Stato materiale | D5: Note | E5: COMUNE | F5: LOCALITA | G5: UBICAZIONE | H5: Coordinate | I5: DEPURATORE ASSOCIATO | J5: RECAPITO EMISSARIO | K5: Tipo di scarico | L5: TIPO | M5: Scadenza autorizzazione Provincia | N5: Atto Provincia n° | O5: Consorzio competente | P5: Scadenza concessione Consorzio | Q5: Atto Consorzio n° | R5: Note AUT./CONC. | T5: NOTE POST PAOLA MARAZZOLI
A6: Governolo
B7: SF-RNC-LAM | C7: OK | D7: Il sollevamento ha Q fortemente limitante causa mandate piccole. Questo però è in accordo con le capacità ridotte del dep. Per cui si decide di fissare Q effettiva a 30 m3/h | E7: Roncoferraro | F7: Governolo | G7: via Lamarmora | H7: 45.0908505, 10.9640945 | I7: Roncoferraro (Governolo) | J7: Dugale di Governolo | L7: in testa impianto di depurazione | M7: 45180 | N7: n° PD / 958 del 11/09/2019 | O7: TDM | P7: IN CORSO | R7: Mandata richiesta di rinnovo in provincia in data 5.09.2023 - monitorare rilascio - SOLLECITARE?
A8: Brusatasso
B9: SF-PGN-KIN | C9: DA VERIFICARE | E9: Pegognaga | F9: Polesine | G9: Via Martin Luther King | H9: 44.984018, 10.811299 | I9: Brusatasso | J9: fosso collegato al Po Vecchio | L9: in testa impianto sollevamento | M9: 2020 | N9: n° PD / 600 del 31/03/2016 | O9: Consorzio di Bonifica Terre dei Gonzaga in Destra Po | P9: DA RICHIEDERE ? | R9: ci sono nulla osta del consorzio - necessario verificare se poi sono stati effettivamente chiusi con rilascio concessione o no
B10: SF-PGN-MAZ | C10: DA VERIFICARE | E10: Pegognaga | F10: Polesine | G10: P.za Mazzini | H10: 44.985095, 10.802363 | I10: Brusatasso | J10: Brusatasso | L10: in testa impianto sollevamento | M10: 2021 | N10: n° PD / 1508 del 22/11/2017 | O10: Consorzio di Bonifica Terre dei Gonzaga in Destra Po | P10: DA RICHIEDERE ? | R10: ci sono nulla osta del consorzio - necessario verificare se poi sono stati effettivamente chiusi con rilascio concessione o no
B11: SF-SZZ-BRU | C11: DA VERIFICARE | E11: Suzzara | F11: Capoluogo | G11: v.le Pace | H11: 44.9856333, 10.7757983 | I11: Brusatasso | J11: Canale Correggioli | L11: in testa impianto di depurazione | M11: 44807 | N11: n° PD / 989 del 03/09/2018 | O11: Consorzio di Bonifica Terre dei Gonzaga in Destra Po | P11: DA RICHIEDERE ? | R11: ci sono nulla osta del consorzio - necessario verificare se poi sono stati effettivamente chiusi con rilascio concessione o no
A12: Gerbolina
B13: SF-PMP-NOC | C13: OK | E13: Pomponesco | F13: Salina | G13: via Nocidella | H13: 44.94989734952731, 10.578134922617812 | I13: Gerbolina | J13: Fossato Salina (tratto tombato) | L13: in testa impianto sollevamento | N13: DA FARE | O13: fosso privato afferente canale consortile - n.a. | P13: DA VALUTARE | R13: Presente cartella con tutto il materiale ma non capisco se inoltrato - chiedere Laura
B14: SF-VDN-GER | C14: OK | E14: Viadana | F14: Gerbolina | G14: Via Gerbolina | H14: 44.95099, 10.54789 | I14: Gerbolina | J14: Fosso Baghella | L14: in testa impianto sollevamento | M14: 45619 | N14: n° PD / 1067 del 17/11/2020 | O14: Navarolo-Agro Cremonese Mantovano | P14: 51866 | Q14: N°1939 del 29/08/2024 | R14: IN CORSO RINNOVO AUTORIZZAZIONE - mandato in data 11/09/23
A15: Castelbelforte
B16: SF-CSB-BER | C16: DA AGGIORNARE | E16: Castelbelforte | F16: Capoluogo | G16: Via Bersaglieri | H16: 45.21922526256204, 10.892481471677195 | I16: Castelbelforte (Capoluogo) | L16: di testa rete | N16: DA FARE | O16: ??
B17: SF-CSB-CAV | C17: DA AGGIORNARE | E17: Castelbelforte | F17: Capoluogo | G17: Via Cavour 51 | H17: 45.20981, 10.890266 | I17: Castelbelforte (Capoluogo) | J17: Fossa Molinella | L17: in testa impianto sollevamento | M17: 44674 | N17: n° PD / 481 del 20/04/2018 | O17: Regione Lombardia - SIPIUI | P17: DA RICHIEDERE
B18: SF-CSB-CSB | C18: DA AGGIORNARE | E18: Castelbelforte | F18: Capoluogo | G18: c/o impianto di depurazione | H18: 45.208606, 10.89703 | I18: Castelbelforte (Capoluogo) | J18: Fossetta Castelbelforte | L18: in testa impianto di depurazione | N18: n° PD 480 del 20/04/2018 | O18: TDM | P18: DA RICHIEDERE
B19: SF-CSB-DON | C19: DA AGGIORNARE | E19: Castelbelforte | F19: Capoluogo | G19: via Donatori AVIS | H19: 45.21893741810397, 10.893251048471777 | I19: Castelbelforte (Capoluogo) | L19: di testa rete | N19: DA FARE | O19: ??
B20: SF-CSB-PAR | C20: DA AGGIORNARE | E20: Castelbelforte | F20: Capoluogo | G20: Via Boselli/Via Mazzini | H20: 45.215997, 10.894037 | I20: Castelbelforte (Capoluogo) | J20: Roggia Essere (da Staz. Soll. acque bianche CSB-MAZ) | K20: pompato | L20: di rete | M20: 2017 | N20: n° 22/112 del 4/06/2013 | O20: TDM | P20: DA RICHIEDERE | R20: IN RINNOVO dal 2016? non l'ho trovato
B21: SF-CSB-PES | C21: DA AGGIORNARE | E21: Castelbelforte | F21: Capoluogo | G21: Via Pescine, 6 | H21: 45.2177, 10.895779 | I21: Castelbelforte (Capoluogo) | J21: Allegrezzola di Castelbelforte | K21: pompato | L21: in testa impianto sollevamento | M21: 44674 | N21: n° PD / 482 DEL 20/04/2018 | O21: Regione Lombardia - SIPIUI | P21: DA RICHIEDERE
B22: SF-CSB-ROS | C22: DA AGGIORNARE | E22: Castelbelforte | F22: Capoluogo | G22: Via Rossa/Via Marconi | H22: 45.212445, 10.896071 | I22: Castelbelforte (Capoluogo) | J22: Roggia Essere (da Staz. Soll. acque bianche CSB-ROS) | K22: pompato | L22: di rete | M22: 2017 | N22: n° 22/110 del 4/06/2013 | O22: TDM | P22: DA RICHIEDERE | R22: IN RINNOVO dal 2016? non l'ho trovato
B23: SF-CSB-ZAN | C23: DA AGGIORNARE | D23: Il derivatore è in realtà un'apertura verso un'altra camera, da cui parte un circolare ø700 cls (archivio TEA). | E23: Castelbelforte | F23: Capoluogo | G23: Via Zaniboni/Via Cavour | H23: 45.212485, 10.891091 | I23: Castelbelforte (Capoluogo) | J23: Fossetta Castelbelforte (Scarica attraverso rete acque piovane) | K23: tramite condotta meteo | L23: di rete | M23: - | N23: in meteo - chiedere al comune | O23: n.a. - rete meteorica in fosso afferente | P23: n.a. | Q23: -
A24: Casteld'ario
B25: SF-CSD-ALL | C25: DA AGGIORNARE | E25: Castel D' Ario | F25: Capoluogo | G25: via S. Allende / via F. Cervi | H25: 45.188317, 10.969825 | I25: Castel D'Ario (Capoluogo) | J25: Scolo Frassinara (da rete meteorica) | K25: tramite condotta meteo | L25: di rete | M25: 45412 | N25: in meteo - chiedere al comune - n° PD / 416 del 30/04/2020 | O25: n.a. - rete meteorica in fosso afferente | P25: n.a. | Q25: -
B26: SF-CSD-ARD | C26: DA AGGIORNARE | D26: considerata una pendenza del 4% per farlo "tornare" superiore a 20 l/s. (anziché il valore "da CAD fornito" del 2.3%) | E26: Castel D' Ario | F26: Capoluogo | G26: via Fosse Ardeatine /SP31 | H26: 45.194841, 10.977597 | I26: Castel D'Ario (Capoluogo) | J26: Condotto Fontana (da fosso tombato) | L26: di rete | M26: 45412 | N26: n° PD / 423 del 30/04/2020 | O26: fosso privato afferente canale consortile - n.a. | P26: n.a. | Q26: -
B27: SF-CSD-CSD1 | C27: DA AGGIORNARE | E27: Castel D' Ario | F27: Capoluogo | G27: Area Depuratore | H27: 45.186605, 10.983417 | I27: Castel D'Ario (Capoluogo) | J27: Fossa Molinella | L27: in testa impianto di depurazione | M27: 45412 | N27: n° PD / 425 del 30/04/2020 | O27: Regione Lombardia - SIPIUI | P27: DA RICHIEDERE
B28: SF-CSD-CSD2 | C28: DA AGGIORNARE | D28: Qs<Pavv | E28: Castel D' Ario | F28: Capoluogo | G28: Via Trieste (non su strada, in campo privato) | H28: 45.187662, 10.981388 | I28: Castel D'Ario (Capoluogo) | J28: Fossa Molinella | L28: di rete | M28: 45423 | N28: n° PD / 443 del 11/05/2020 | O28: Regione Lombardia - SIPIUI | P28: DA RICHIEDERE
B29: SF-CSD-GAS | C29: DA AGGIORNARE | E29: Castel D' Ario | F29: Capoluogo | G29: Via De Gasperi | H29: 45.18810737371577, 10.968887458070576 | I29: Castel D'Ario (Capoluogo) | J29: Scolo Frassinara | L29: di testa rete | M29: 45424 | N29: n° PD / 447 del 12/05/2020 | O29: Regione Lombardia - SIPIUI | P29: DA RICHIEDERE
B30: SF-CSD-GAS2 | C30: DA AGGIORNARE | E30: Castel D' Ario | F30: Capoluogo | G30: Via De Gasperi | H30: 45.188192631240454, 10.968749802712578 | I30: Castel D'Ario (Capoluogo) | J30: Scolo Frassinara | L30: di testa rete | M30: 45412 | N30: ?? | O30: Regione Lombardia - SIPIUI | P30: DA RICHIEDERE | R30: NON trovata nell'elenco delle autorizzazioni degli sfiori di casteldario
B31: SF-CSD-GRA2 | C31: DA AGGIORNARE | E31: Castel D' Ario | F31: Capoluogo | G31: Canale Marchesano (da rete meteorica) | H31: 45.183695, 10.971836 | I31: Castel D'Ario (Capoluogo) | J31: Canale Marchesano (da rete meteorica) | K31: tramite condotta meteo | L31: di rete | M31: 45412 | N31: in meteo - chiedere al comune - n° PD / 419 30/04/2020 | O31: n.a. - rete meteorica in fosso afferente | P31: n.a. | Q31: -
B32: SF-CSD-KIN | C32: DA AGGIORNARE | E32: Castel D' Ario | F32: Capoluogo | G32: via King / via Gramsci | H32: 45.186053, 10.971092 | I32: Castel D'Ario (Capoluogo) | J32: Canale Marchesano (da rete meteorica) | K32: tramite condotta meteo | L32: di rete | M32: 45412 | N32: in meteo - chiedere al comune | O32: n.a. - rete meteorica in fosso afferente | P32: n.a. | Q32: -
B33: SF-CSD-MAG | C33: DA AGGIORNARE | E33: Castel D' Ario | F33: Capoluogo | G33: via I° Maggio n. 7 | H33: 45.189646128421245, 10.979481755763011 | I33: Castel D'Ario (Capoluogo) | J33: Fossa Molinella | L33: di testa rete | M33: 45412 | N33: n° PD / 417 del 30/04/2020 | O33: Regione Lombardia - SIPIUI
B34: SF-CSD-MAR | C34: DA AGGIORNARE | E34: Castel D' Ario | F34: Capoluogo | G34: via Marzabotto / SP31 | H34: 45.195222, 10.977957 | I34: Castel D'Ario (Capoluogo) | J34: Condotto Fontana (da fosso tombato) | L34: di rete | M34: 45412 | N34: n° PD / 421 del 30/04/2020 | O34: fosso privato afferente canale consortile - n.a. | P34: n.a. | Q34: -
B35: SF-CSD-MAT1 | C35: DA AGGIORNARE | E35: Castel D' Ario | F35: Capoluogo | G35: via Matteotti n.11 | H35: 45.1889, 10.973278 | I35: Castel D'Ario (Capoluogo) | J35: Condotto Dossi Pezze (da fosso tombato) | L35: di rete | M35: 45446 | N35: n° PD / 513 del 03/06/2020 | O35: fosso privato afferente canale consortile - n.a. | P35: n.a. | Q35: -
B36: SF-CSD-MAT2 | C36: DA AGGIORNARE | E36: Castel D' Ario | F36: Capoluogo | G36: via Matteotti | H36: 45.186972, 10.97091 | I36: Castel D'Ario (Capoluogo) | J36: Scolo Frassinara (da rete meteorica) | K36: tramite condotta meteo | L36: di rete | M36: 45412 | N36: in meteo - chiedere al comune - n° PD / 536 del 11/06/2020 | O36: n.a. - rete meteorica in fosso afferente | P36: n.a. | Q36: -
B37: SF-CSD-MGR | C37: DA AGGIORNARE | D37: considerata una pendenza del 0.6% per farlo "tornare" superiore a 20 l/s. (anziché il valore "da CAD fornito" del 0.16%) | E37: Castel D' Ario | F37: Capoluogo | G37: via Monte Grappa / SP31 | H37: 45.195607, 10.978316 | I37: Castel D'Ario (Capoluogo) | J37: Condotto Fontana (da fosso tombato) | L37: di rete | M37: 45412 | N37: n° PD / 420 del 30/04/2020 | O37: fosso privato afferente canale consortile - n.a. | P37: n.a. | Q37: -
B38: SF-CSD-ROM | C38: DA AGGIORNARE | E38: Castel D' Ario | F38: Capoluogo | G38: via Roma | H38: 45.190952, 10.970874 | I38: Castel D'Ario (Capoluogo) | J38: Condotto Dossi Pezze | L38: in testa impianto sollevamento | M38: 45412 | N38: n° PD / 414 del 30/04/2020 | O38: TDM | P38: DA RICHIEDERE
B39: SF-CSD-SET | C39: DA AGGIORNARE | E39: Castel D' Ario | F39: Capoluogo | G39: via XX settembre / piazza Garibaldi | H39: 45.189144, 10.975078 | I39: Castel D'Ario (Capoluogo) | J39: Condotto Dossi Pezze | L39: di rete | M39: 45451 | N39: n° PD / 530 del 08/06/2020 | O39: TDM | P39: DA RICHIEDERE
B40: SF-CSD-VEN1 | C40: DA AGGIORNARE | E40: Castel D' Ario | F40: Capoluogo | G40: via Veneto / Via I° Maggio | H40: 45.190151, 10.977507 | I40: Castel D'Ario (Capoluogo) | J40: fosso Molinella | L40: in testa impianto sollevamento | M40: 45412 | N40: n° PD / 424 del 30/04/2020 | O40: Regione Lombardia - SIPIUI | P40: DA RICHIEDERE
A41: Villa Pasquali
...

Sheet Sfiori Qs<Pavv
C2: Qs [l/s] | D2: Pavv [l/s] | G2: Adeguamento | H2: Qs post adeguamento [l/s] | I2: Tipo sfioratore
B3: SF-CSS-MED2 | C3: 197.49 | D3: 203.90728 | F3: Intervento | G3: Modificare pendenza da 0,0024 a 0,003 | H3: 223 | I3: B | J3: Da chiudere post adeguamento soll di valle | O3: Verifica scala di deflusso MED3
G4: Alzo soglia di 2 cm | H4: 214 | I4: B
G5: Alzo soglia di 52 cm | H5: 591 | I5: A
B6: SF-CMM-CMM | C6: 11.35 | D6: 13.498264 | F6: Intervento | G6: Cambiare assetto del sollevamento limitante | J6: Sollevamento verificato, effettivamente risulta Qsoll=11,4 l/s. Giacomo dice che il depuratore non risulta verificato neanche con la portata dichiarata di 11 l/s, quindi possiamo sistemare gli elaborati dello sfioro in modo che risulti conforme (ritocco il punto di funzionamento del soll), lato depuratore hanno fatto storie anche per il rinnovo di qualche anno fa, "in qualche modo faremo". Servirebbe una seconda vasca di sedimentazione
B8: SF-CSD-CSD2 | C8: 38.23 | D8: 42.54 | F8: Intervento | G8: Modificare pendenza da 0,005 a 0,007 | H8: 45 | I8: B | J8: Intervento da realizzare
G9: Alzo soglia di 2 cm | H9: 45 | I9: B
G10: Alzo soglia di 11 cm e consedero pendenza di 0.007 | H10: 85 | I10: A
B11: SF-RVL-RVL | C11: 9.45 | D11: 35.97 | F11: Intervento | G11: Alzare la soglia di 30 cm (o considerare pendenza di 0.007 anziché 0.0004) e cambiare assetto al sollevamento di valle (Qsoll attuale=18.8 l/s) | J11: La relazione aggiornata non considera il sollevamento, il quale è limitante. Senza sollevamento Qs=92,37 l/s (hanno considerato una soglia che in realtà deve essere ancora fatta, ma è già in programma). | O11: Capacità sollevamento (pompe in parallelo) è di 25 l/s, pompe cambiate da poco

Sheet sfiori per SIPIUI
A1: OK - RELAZIONI A POSTO
A2: E' SIPIUI ?
A3: DA FARE?
